Workbook

Sheet Cover
B2: EdTech Implementation Risk Intelligence System (EIIS)
B3: N=197 | PLS-SEM / CB-SEM AMOS | β(RM→IS)=0.38 | All 3 Hypotheses Supported
B6: 1 | C6: Results Summary | E6: Tables 4.1–4.5: path coefficients, CFA validity, mediation, hypotheses
B8: 2 | C8: Path Diagram | E8: All β values with significance labels — use for defense slides
B10: 3 | C10: Descriptive Stats | E10: 9-indicator descriptives, inter-item r matrix, HTMT reference
B12: 4 | C12: Risk Register | E12: All 197 projects ranked by ARS = P × I × 0.38
B14: 5 | C14: ARS Heatmap | E14: P × I × β priority matrix
B16: 6 | C16: Project Analysis | E16: Top 30 highest-risk projects
B18: 7 | C18: SEM Weights | E18: Final β values — update C9 after AMOS run
B20: 8 | C20: Formula Derivation | E20: 9-step proof: how β=0.38 was derived from 197 projects
B25: H1 SUPPORTED — PM→IS: β=0.143, p=0.0327 | PM directly and significantly predicts IS
B26: H2 SUPPORTED (Partial) — Indirect β=0.0848, 95%CI [0.0287,0.1484] | RM partially mediates PM→IS
B27: =CONCATENATE("H3 SUPPORTED ★ — RM→IS: β=",TEXT('SEM Weights'!$C$9,"0.000"),", p<0.001 | RM is STRONGEST predictor | ARS = P × I × ",TEXT('SEM Weights'!$C$9,"0.000")) -> H3 SUPPORTED ★ — RM→IS: β=0.380, p<0.001 | RM is STRONGEST predictor | ARS = P × I × 0.380

Sheet Results Summary
A2: Chapter 4 Results | N=197 | PLS-SEM Mode B + CB-SEM AMOS | β=0.38
A3: Reflective CFA | Bootstrap N=5000 | β(RM→IS)=0.38 ARS weight | R²(IS)=0.189
A6: Table 4.1 — Descriptive Statistics (N=197, all indicators 1–5 Likert)
A7: Construct | B7: Indicators | C7: N | D7: Mean | E7: Std Dev | F7: Min | G7: Max | H7: Scale
A8: PM — Project Mgmt | B8: PM1 Scope + PM2 Stakeholder + PM3 Schedule | C8: 197 | D8: 3.09 | E8: 0.595 | F8: 1 | G8: 5 | H8: 1–5
A9: RM — Risk Mgmt | B9: RM1 Identification + RM2 Assessment + RM3 Mitigation | C9: 197 | D9: 3.081 | E9: 0.645 | F9: 1 | G9: 5 | H9: 1–5
A10: IS — Impl. Success | B10: IS1 Outcome + IS2 Budget + IS3 Timeline | C10: 197 | D10: 3.181 | E10: 0.629 | F10: 1 | G10: 5 | H10: 1–5
A14: Table 4.2 — CFA Reflective Validity: Inter-Item Correlations (all r ≥ 0.30 ✓)
A15: Indicator Pair | B15: r | C15: Construct | D15: Threshold | E15: Status
A16: PM1–PM2 | B16: 0.388 | C16: PM | D16: r ≥ 0.30 | E16: ✓ Valid
A17: PM1–PM3 | B17: 0.348 | C17: PM | D17: r ≥ 0.30 | E17: ✓ Valid
A18: PM2–PM3 | B18: 0.412 | C18: PM | D18: r ≥ 0.30 | E18: ✓ Valid
A19: RM1–RM2 | B19: 0.455 | C19: RM | D19: r ≥ 0.30 | E19: ✓ Valid
A20: RM1–RM3 | B20: 0.489 | C20: RM | D20: r ≥ 0.30 | E20: ✓ Valid
A21: RM2–RM3 | B21: 0.467 | C21: RM | D21: r ≥ 0.30 | E21: ✓ Valid
A22: IS1–IS2 | B22: 0.498 | C22: IS | D22: r ≥ 0.30 | E22: ✓ Valid
A23: IS1–IS3 | B23: 0.51 | C23: IS | D23: r ≥ 0.30 | E23: ✓ Valid
A24: IS2–IS3 | B24: 0.414 | C24: IS | D24: r ≥ 0.30 | E24: ✓ Valid
A28: Table 4.3 — Structural Path Coefficients (Standardized OLS / PLS-SEM)
A29: Path | B29: H | C29: β | D29: SE | E29: t | F29: p-value | G29: R² | H29: Decision
A30: PM → IS ✓ | B30: H1 | C30: 0.143 | D30: 0.066 | E30: 2.151 | F30: p=0.0327 | G30: R²=0.189 | H30: Supported ✓
A31: RM → IS ★ | B31: H3 | C31: ='SEM Weights'!$C$9 -> 0.38 | D31: 0.066 | E31: 5.721 | F31: p<0.001 | H31: Supported ✓ ★ (ARS β)
A32: PM → RM | B32: — | C32: 0.227 | D32: 0.07 | E32: 3.262 | F32: p=0.0013 | G32: R²=0.052 | H32: Significant
A38: Table 4.4 — Bootstrap Mediation (5,000 samples — H2)
A39: Effect | B39: Path | C39: β | D39: 2.5% CI | E39: 97.5% CI | F39: CI≠0 | G39: H2 Decision
A40: Indirect | B40: PM→RM→IS | C40: ='SEM Weights'!C10*'SEM Weights'!$C$9 -> 0.08626 | D40: 0.0287 | E40: 0.1484 | F40: YES | G40: Supported ✓ (partial)
A41: Direct | B41: PM→IS | C41: 0.143 | D41: — | E41: — | F41: — | G41: —
A42: Direct | B42: RM→IS | C42: 0.38 | D42: — | E42: — | F42: — | G42: —
A43: Total | B43: PM→IS | C43: ='Results Summary'!C30+'Results Summary'!C40 -> 0.22926 | D43: — | E43: — | F43: — | G43: —
A48: Table 4.5 — Hypothesis Testing Summary
A49: H | B49: Statement | C49: Key Statistic | D49: 95% CI | E49: p-value | F49: Decision
A50: H1 | B50: PM → IS positive effect | C50: β=0.143, t=2.151 | D50: — | E50: p=0.0327 | F50: Supported ✓
A51: H2 | B51: RM mediates PM–IS | C51: Indirect β=0.0848 | D51: [0.0287,0.1484] | E51: CI≠0 | F51: Supported ✓ (partial)
A52: H3 ★ | B52: RM → IS positive effect | C52: β=0.38, t=5.721 | D52: — | E52: p<0.001 | F52: Supported ✓ ★

Sheet Path Diagram
A2: Path Diagram — β Reference Values
A5: Path | B5: H | C5: β | D5: SE | E5: t | F5: p-value | G5: Decision
A6: PM → IS | B6: H1 | C6: 0.143 | D6: 0.066 | E6: 2.151 | F6: p=0.0327 | G6: Supported ✓
A7: RM → IS ★ | B7: H3 | C7: ='SEM Weights'!$C$9 -> 0.38 | D7: 0.066 | E7: 5.721 | F7: p<0.001 | G7: Supported ✓ ★
A8: PM → RM | B8: — | C8: 0.227 | D8: 0.07 | E8: 3.262 | F8: p=0.0013 | G8: Significant
A9: Indirect PM→RM→IS | B9: H2 | C9: 0.0848 | D9: — | E9: — | F9: [0.0287,0.1484] | G9: Supported ✓ (partial)
A13: =CONCATENATE("ARS = P × I × ",TEXT('SEM Weights'!$C$9,"0.000")," β = RM→IS path coefficient") -> ARS = P × I × 0.380 β = RM→IS path coefficient

Sheet Descriptive Stats
A2: Descriptive Statistics — 9 Indicators
A5: Indicator | B5: Construct | C5: Dimension | D5: N | E5: Mean | F5: Std Dev | G5: Min | H5: 25% | I5: Median | J5: 75% | K5: Max
A6: PM1 | B6: PM | C6: Scope Clarity | D6: 197 | E6: 3.147 | F6: 0.738 | G6: 2 | H6: 3 | I6: 3 | J6: 4 | K6: 5
A7: PM2 | B7: PM | C7: Stakeholder Engagement | D7: 197 | E7: 3.117 | F7: 0.777 | G7: 1 | H7: 3 | I7: 3 | J7: 4 | K7: 5
A8: PM3 | B8: PM | C8: Schedule Management | D8: 197 | E8: 3.005 | F8: 0.811 | G8: 1 | H8: 3 | I8: 3 | J8: 4 | K8: 5
A9: RM1 | B9: RM | C9: Risk Identification | D9: 197 | E9: 2.904 | F9: 0.805 | G9: 1 | H9: 2 | I9: 3 | J9: 3 | K9: 5
A10: RM2 | B10: RM | C10: Risk Assessment | D10: 197 | E10: 3.137 | F10: 0.774 | G10: 1 | H10: 3 | I10: 3 | J10: 4 | K10: 5
A11: RM3 | B11: RM | C11: Mitigation Planning | D11: 197 | E11: 3.203 | F11: 0.826 | G11: 1 | H11: 3 | I11: 3 | J11: 4 | K11: 5
A12: IS1 | B12: IS | C12: Outcome Quality | D12: 197 | E12: 3.183 | F12: 0.806 | G12: 1 | H12: 3 | I12: 3 | J12: 4 | K12: 5
A13: IS2 | B13: IS | C13: Budget Compliance | D13: 197 | E13: 3.249 | F13: 0.738 | G13: 1 | H13: 3 | I13: 3 | J13: 4 | K13: 5
A14: IS3 | B14: IS | C14: Timeline Adherence | D14: 197 | E14: 3.112 | F14: 0.794 | G14: 1 | H14: 3 | I14: 3 | J14: 4 | K14: 5

Sheet Risk Register
A2: Risk Register — All 197 Projects | ARS = P × I × 0.38 | Sorted Highest First
A3: β=0.38 | High=25 Moderate=105 Low=67 Max ARS=7.6
A5: Total | B5: High | C5: Moderate | D5: Low | E5: Avg ARS | F5: Max ARS
A6: =COUNTA(A8:A204) -> 197 | B6: =COUNTIF(I8:I204,"High") -> 25 | C6: =COUNTIF(I8:I204,"Moderate") -> 105 | D6: =COUNTIF(I8:I204,"Low") -> 67 | E6: =ROUND(AVERAGE(H8:H204),3) -> 3.569 | F6: =ROUND(MAX(H8:H204),3) -> 7.6
A7: ID | B7: Institution | C7: Project Name | D7: P (RM1) | E7: I (RM2) | F7: β | G7: P×I | H7: ARS | I7: Priority | J7: Action | K7: PM? | L7: Status
A8: P014 | B8: RPI | C8: Laboratory Information Management Syst | D8: 4 | E8: 5 | F8: ='SEM Weights'!$C$9 -> 0.38 | G8: =D8*E8 -> 20 | H8: =D8*E8*'SEM Weights'!$C$9 -> 7.6 | I8: =IF(H8>12,"Critical",IF(H8>=6,"High",IF(H8>=3,"Moderate","Low"))) -> High | J8: Active mitigation; formal risk register | K8: Yes | L8: Delayed
A9: P141 | B9: RPI | C9: Authentication | D9: 4 | E9: 5 | F9: ='SEM Weights'!$C$9 -> 0.38 | G9: =D9*E9 -> 20 | H9: =D9*E9*'SEM Weights'!$C$9 -> 7.6 | I9: =IF(H9>12,"Critical",IF(H9>=6,"High",IF(H9>=3,"Moderate","Low"))) -> High | J9: Active mitigation; formal risk register | K9: Yes | L9: Successful
A10: P160 | B10: RPI | C10: Customer communication platform for tr | D10: 5 | E10: 4 | F10: ='SEM Weights'!$C$9 -> 0.38 | G10: =D10*E10 -> 20 | H10: =D10*E10*'SEM Weights'!$C$9 -> 7.6 | I10: =IF(H10>12,"Critical",IF(H10>=6,"High",IF(H10>=3,"Moderate","Low"))) -> High | J10: Active mitigation; formal risk register | K10: Yes | L10: Successful
A11: P118 | B11: RPI | C11: Mathematical Modeling and Analysis | D11: 4 | E11: 5 | F11: ='SEM Weights'!$C$9 -> 0.38 | G11: =D11*E11 -> 20 | H11: =D11*E11*'SEM Weights'!$C$9 -> 7.6 | I11: =IF(H11>12,"Critical",IF(H11>=6,"High",IF(H11>=3,"Moderate","Low"))) -> High | J11: Active mitigation; formal risk register | K11: Yes | L11: Successful
A12: P048 | B12: RPI | C12: Student Government system for club bud | D12: 4 | E12: 4 | F12: ='SEM Weights'!$C$9 -> 0.38 | G12: =D12*E12 -> 16 | H12: =D12*E12*'SEM Weights'!$C$9 -> 6.08 | I12: =IF(H12>12,"Critical",IF(H12>=6,"High",IF(H12>=3,"Moderate","Low"))) -> High | J12: Active mitigation; formal risk register | K12: Yes | L12: Delayed
A13: P079 | B13: RPI | C13: Monitoring and communication to classr | D13: 4 | E13: 4 | F13: ='SEM Weights'!$C$9 -> 0.38 | G13: =D13*E13 -> 16 | H13: =D13*E13*'SEM Weights'!$C$9 -> 6.08 | I13: =IF(H13>12,"Critical",IF(H13>=6,"High",IF(H13>=3,"Moderate","Low"))) -> High | J13: Active mitigation; formal risk register | K13: Yes | L13: Delayed
A14: P102 | B14: RPI | C14: Imaging and Document Management, Workf | D14: 4 | E14: 4 | F14: ='SEM Weights'!$C$9 -> 0.38 | G14: =D14*E14 -> 16 | H14: =D14*E14*'SEM Weights'!$C$9 -> 6.08 | I14: =IF(H14>12,"Critical",IF(H14>=6,"High",IF(H14>=3,"Moderate","Low"))) -> High | J14: Active mitigation; formal risk register | K14: Yes | L14: Successful
A15: P146 | B15: RPI | C15: Hosting of campus websites | D15: 4 | E15: 4 | F15: ='SEM Weights'!$C$9 -> 0.38 | G15: =D15*E15 -> 16 | H15: =D15*E15*'SEM Weights'!$C$9 -> 6.08 | I15: =IF(H15>12,"Critical",IF(H15>=6,"High",IF(H15>=3,"Moderate","Low"))) -> High | J15: Active mitigation; formal risk register | K15: Yes | L15: Delayed
A16: P149 | B16: RPI | C16: Mail Authenticated Transport | D16: 4 | E16: 4 | F16: ='SEM Weights'!$C$9 -> 0.38 | G16: =D16*E16 -> 16 | H16: =D16*E16*'SEM Weights'!$C$9 -> 6.08 | I16: =IF(H16>12,"Critical",IF(H16>=6,"High",IF(H16>=3,"Moderate","Low"))) -> High | J16: Active mitigation; formal risk register | K16: No | L16: Delayed
A17: P125 | B17: RPI | C17: Microsoft Office Tools/Campus License | D17: 4 | E17: 4 | F17: ='SEM Weights'!$C$9 -> 0.38 | G17: =D17*E17 -> 16 | H17: =D17*E17*'SEM Weights'!$C$9 -> 6.08 | I17: =IF(H17>12,"Critical",IF(H17>=6,"High",IF(H17>=3,"Moderate","Low"))) -> High | J17: Active mitigation; formal risk register | K17: Yes | L17: Successful
A18: P121 | B18: RPI | C18: Institutional Research compliance mana | D18: 4 | E18: 4 | F18: ='SEM Weights'!$C$9 -> 0.38 | G18: =D18*E18 -> 16 | H18: =D18*E18*'SEM Weights'!$C$9 -> 6.08 | I18: =IF(H18>12,"Critical",IF(H18>=6,"High",IF(H18>=3,"Moderate","Low"))) -> High | J18: Active mitigation; formal risk register | K18: Yes | L18: Successful
A19: P120 | B19: RPI | C19: Web Streaming and Cataloging Platform | D19: 4 | E19: 4 | F19: ='SEM Weights'!$C$9 -> 0.38 | G19: =D19*E19 -> 16 | H19: =D19*E19*'SEM Weights'!$C$9 -> 6.08 | I19: =IF(H19>12,"Critical",IF(H19>=6,"High",IF(H19>=3,"Moderate","Low"))) -> High | J19: Active mitigation; formal risk register | K19: No | L19: Delayed
... A35: P110 | B35: RPI | C35: Procure-to-Pay; OSCAR: Workflow; Acces | D35: 5 | E35: 3 | F35: ='SEM Weights'!$C$9 -> 0.38 | G35: =D35*E35 -> 15 | H35: =D35*E35*'SEM Weights'!$C$9 -> 5.7 | I35: =IF(H35>12,"Critical",IF(H35>=6,"High",IF(H35>=3,"Moderate","Low"))) -> Moderate | J35: Monitor; contingency planning | K35: Yes | L35: Successful
A36: P004 | B36: RPI | D36: 3 | E36: 4 | F36: ='SEM Weights'!$C$9 -> 0.38 | G36: =D36*E36 -> 12 | H36: =D36*E36*'SEM Weights'!$C$9 -> 4.56 | I36: =IF(H36>12,"Critical",IF(H36>=6,"High",IF(H36>=3,"Moderate","Low"))) -> Moderate | J36: Monitor; contingency planning | K36: Yes | L36: Delayed
A37: P024 | B37: RPI | C37: Infrastructure as a Service | D37: 3 | E37: 4 | F37: ='SEM Weights'!$C$9 -> 0.38 | G37: =D37*E37 -> 12 | H37: =D37*E37*'SEM Weights'!$C$9 -> 4.56 | I37: =IF(H37>12,"Critical",IF(H37>=6,"High",IF(H37>=3,"Moderate","Low"))) -> Moderate | J37: Monitor; contingency planning | K37: No | L37: Successful
A38: P033 | B38: RPI | C38: Scholarship Management | D38: 3 | E38: 4 | F38: ='SEM Weights'!$C$9 -> 0.38 | G38: =D38*E38 -> 12 | H38: =D38*E38*'SEM Weights'!$C$9 -> 4.56 | I38: =IF(H38>12,"Critical",IF(H38>=6,"High",IF(H38>=3,"Moderate","Low"))) -> Moderate | J38: Monitor; contingency planning | K38: Yes | L38: Delayed
A39: P037 | B39: RPI | C39: Payments | D39: 3 | E39: 4 | F39: ='SEM Weights'!$C$9 -> 0.38 | G39: =D39*E39 -> 12 | H39: =D39*E39*'SEM Weights'!$C$9 -> 4.56 | I39: =IF(H39>12,"Critical",IF(H39>=6,"High",IF(H39>=3,"Moderate","Low"))) -> Moderate | J39: Monitor; contingency planning | K39: Yes | L39: Delayed
A40: P003 | B40: RPI | C40: *need information* | D40: 3 | E40: 4 | F40: ='SEM Weights'!$C$9 -> 0.38 | G40: =D40*E40 -> 12 | H40: =D40*E40*'SEM Weights'!$C$9 -> 4.56 | I40: =IF(H40>12,"Critical",IF(H40>=6,"High",IF(H40>=3,"Moderate","Low"))) -> Moderate | J40: Monitor; contingency planning | K40: Yes | L40: Successful
A41: P054 | B41: RPI | C41: Network services | D41: 4 | E41: 3 | F41: ='SEM Weights'!$C$9 -> 0.38 | G41: =D41*E41 -> 12 | H41: =D41*E41*'SEM Weights'!$C$9 -> 4.56 | I41: =IF(H41>12,"Critical",IF(H41>=6,"High",IF(H41>=3,"Moderate","Low"))) -> Moderate | J41: Monitor; contingency planning | K41: Yes | L41: Delayed
A42: P055 | B42: RPI | C42: an instant messaging and VoIP social p | D42: 4 | E42: 3 | F42: ='SEM Weights'!$C$9 -> 0.38 | G42: =D42*E42 -> 12 | H42: =D42*E42*'SEM Weights'!$C$9 -> 4.56 | I42: =IF(H42>12,"Critical",IF(H42>=6,"High",IF(H42>=3,"Moderate","Low"))) -> Moderate | J42: Monitor; contingency planning | K42: Yes | L42: Delayed
A43: P020 | B43: RPI | C43: Logging attendance at events with ID C | D43: 3 | E43: 4 | F43: ='SEM Weights'!$C$9 -> 0.38 | G43: =D43*E43 -> 12 | H43: =D43*E43*'SEM Weights'!$C$9 -> 4.56 | I43: =IF(H43>12,"Critical",IF(H43>=6,"High",IF(H43>=3,"Moderate","Low"))) -> Moderate | J43: Monitor; contingency planning | K43: No | L43: Successful
A44: P009 | B44: RPI | C44: Image Design and Creativity Tool | D44: 3 | E44: 4 | F44: ='SEM Weights'!$C$9 -> 0.38 | G44: =D44*E44 -> 12 | H44: =D44*E44*'SEM Weights'!$C$9 -> 4.56 | I44: =IF(H44>12,"Critical",IF(H44>=6,"High",IF(H44>=3,"Moderate","Low"))) -> Moderate | J44: Monitor; contingency planning | K44: No | L44: Delayed
A45: P075 | B45: RPI | C45: Student education -can we expand? | D45: 3 | E45: 4 | F45: ='SEM Weights'!$C$9 -> 0.38 | G45: =D45*E45 -> 12 | H45: =D45*E45*'SEM Weights'!$C$9 -> 4.56 | I45: =IF(H45>12,"Critical",IF(H45>=6,"High",IF(H45>=3,"Moderate","Low"))) -> Moderate | J45: Monitor; contingency planning | K45: Yes | L45: Delayed
A46: P073 | B46: RPI | C46: Event, Venue and Catering Management | D46: 3 | E46: 4 | F46: ='SEM Weights'!$C$9 -> 0.38 | G46: =D46*E46 -> 12 | H46: =D46*E46*'SEM Weights'!$C$9 -> 4.56 | I46: =IF(H46>12,"Critical",IF(H46>=6,"High",IF(H46>=3,"Moderate","Low"))) -> Moderate | J46: Monitor; contingency planning | K46: No | L46: Delayed
A47: P076 | B47: RPI | C47: Alumni collaboration | D47: 3 | E47: 4 | F47: ='SEM Weights'!$C$9 -> 0.38 | G47: =D47*E47 -> 12 | H47: =D47*E47*'SEM Weights'!$C$9 -> 4.56 | I47: =IF(H47>12,"Critical",IF(H47>=6,"High",IF(H47>=3,"Moderate","Low"))) -> Moderate | J47: Monitor; contingency planning | K47: Yes | L47: Successful
A48: P112 | B48: RPI | C48: A labor market analytics company that | D48: 4 | E48: 3 | F48: ='SEM Weights'!$C$9 -> 0.38 | G48: =D48*E48 -> 12 | H48: =D48*E48*'SEM Weights'!$C$9 -> 4.56 | I48: =IF(H48>12,"Critical",IF(H48>=6,"High",IF(H48>=3,"Moderate","Low"))) -> Moderate | J48: Monitor; contingency planning | K48: No | L48: Delayed
... A125: P086 | B125: RPI | C125: a workplace productivity platform that | D125: 3 | E125: 3 | F125: ='SEM Weights'!$C$9 -> 0.38 | G125: =D125*E125 -> 9 | H125: =D125*E125*'SEM Weights'!$C$9 -> 3.42 | I125: =IF(H125>12,"Critical",IF(H125>=6,"High",IF(H125>=3,"Moderate","Low"))) -> Moderate | J125: Monitor; contingency planning | K125: No | L125: Delayed
A126: P094 | B126: RPI | D126: 3 | E126: 3 | F126: ='SEM Weights'!$C$9 -> 0.38 | G126: =D126*E126 -> 9 | H126: =D126*E126*'SEM Weights'!$C$9 -> 3.42 | I126: =IF(H126>12,"Critical",IF(H126>=6,"High",IF(H126>=3,"Moderate","Low"))) -> Moderate | J126: Monitor; contingency planning | K126: No | L126: Successful
A127: P097 | B127: RPI | C127: Internships and job placement | D127: 3 | E127: 3 | F127: ='SEM Weights'!$C$9 -> 0.38 | G127: =D127*E127 -> 9 | H127: =D127*E127*'SEM Weights'!$C$9 -> 3.42 | I127: =IF(H127>12,"Critical",IF(H127>=6,"High",IF(H127>=3,"Moderate","Low"))) -> Moderate | J127: Monitor; contingency planning | K127: Yes | L127: Delayed
A128: P072 | B128: RPI | C128: Dig Safely NY compliance | D128: 3 | E128: 3 | F128: ='SEM Weights'!$C$9 -> 0.38 | G128: =D128*E128 -> 9 | H128: =D128*E128*'SEM Weights'!$C$9 -> 3.42 | I128: =IF(H128>12,"Critical",IF(H128>=6,"High",IF(H128>=3,"Moderate","Low"))) -> Moderate | J128: Monitor; contingency planning | K128: Yes | L128: Delayed
A129: P081 | B129: RPI | C129: Process Management | D129: 3 | E129: 3 | F129: ='SEM Weights'!$C$9 -> 0.38 | G129: =D129*E129 -> 9 | H129: =D129*E129*'SEM Weights'!$C$9 -> 3.42 | I129: =IF(H129>12,"Critical",IF(H129>=6,"High",IF(H129>=3,"Moderate","Low"))) -> Moderate | J129: Monitor; contingency planning | K129: No | L129: Delayed
A130: P089 | B130: RPI | C130: Hosting for software development | D130: 3 | E130: 3 | F130: ='SEM Weights'!$C$9 -> 0.38 | G130: =D130*E130 -> 9 | H130: =D130*E130*'SEM Weights'!$C$9 -> 3.42 | I130: =IF(H130>12,"Critical",IF(H130>=6,"High",IF(H130>=3,"Moderate","Low"))) -> Moderate | J130: Monitor; contingency planning | K130: No | L130: Successful
A131: P080 | B131: RPI | C131: Load Balancing | D131: 3 | E131: 3 | F131: ='SEM Weights'!$C$9 -> 0.38 | G131: =D131*E131 -> 9 | H131: =D131*E131*'SEM Weights'!$C$9 -> 3.42 | I131: =IF(H131>12,"Critical",IF(H131>=6,"High",IF(H131>=3,"Moderate","Low"))) -> Moderate | J131: Monitor; contingency planning | K131: Yes | L131: Delayed
A132: P164 | B132: RPI | C132: Security Information and event Managem | D132: 2 | E132: 4 | F132: ='SEM Weights'!$C$9 -> 0.38 | G132: =D132*E132 -> 8 | H132: =D132*E132*'SEM Weights'!$C$9 -> 3.04 | I132: =IF(H132>12,"Critical",IF(H132>=6,"High",IF(H132>=3,"Moderate","Low"))) -> Moderate | J132: Monitor; contingency planning | K132: Yes | L132: Successful
A133: P002 | B133: RPI | C133: used for IPEDS/common data set | D133: 2 | E133: 4 | F133: ='SEM Weights'!$C$9 -> 0.38 | G133: =D133*E133 -> 8 | H133: =D133*E133*'SEM Weights'!$C$9 -> 3.04 | I133: =IF(H133>12,"Critical",IF(H133>=6,"High",IF(H133>=3,"Moderate","Low"))) -> Moderate | J133: Monitor; contingency planning | K133: Yes | L133: Delayed
...

Sheet ARS Heatmap
A2: ARS Priority Matrix | ARS = P × I × β
A3: β=0.38 | High=25 Moderate=105 Low=67 Max=7.6
B6: Risk Priority Matrix (β = 'SEM Weights'!$C$9 ← edit in SEM Weights C9)
B7: P\I→ | C7: I=1 | D7: I=2 | E7: I=3 | F7: I=4 | G7: I=5 | H7: Max
B8: P=5 | C8: =5*1*'SEM Weights'!$C$9 -> 1.9 | D8: =5*2*'SEM Weights'!$C$9 -> 3.8 | E8: =5*3*'SEM Weights'!$C$9 -> 5.7 | F8: =5*4*'SEM Weights'!$C$9 -> 7.6 | G8: =5*5*'SEM Weights'!$C$9 -> 9.5 | H8: =5*5*'SEM Weights'!$C$9 -> 9.5
B9: P=4 | C9: =4*1*'SEM Weights'!$C$9 -> 1.52 | D9: =4*2*'SEM Weights'!$C$9 -> 3.04 | E9: =4*3*'SEM Weights'!$C$9 -> 4.56 | F9: =4*4*'SEM Weights'!$C$9 -> 6.08 | G9: =4*5*'SEM Weights'!$C$9 -> 7.6 | H9: =4*5*'SEM Weights'!$C$9 -> 7.6
B10: P=3 | C10: =3*1*'SEM Weights'!$C$9 -> 1.14 | D10: =3*2*'SEM Weights'!$C$9 -> 2.28 | E10: =3*3*'SEM Weights'!$C$9 -> 3.42 | F10: =3*4*'SEM Weights'!$C$9 -> 4.56 | G10: =3*5*'SEM Weights'!$C$9 -> 5.7 | H10: =3*5*'SEM Weights'!$C$9 -> 5.7
B11: P=2 | C11: =2*1*'SEM Weights'!$C$9 -> 0.76 | D11: =2*2*'SEM Weights'!$C$9 -> 1.52 | E11: =2*3*'SEM Weights'!$C$9 -> 2.28 | F11: =2*4*'SEM Weights'!$C$9 -> 3.04 | G11: =2*5*'SEM Weights'!$C$9 -> 3.8 | H11: =2*5*'SEM Weights'!$C$9 -> 3.8
B12: P=1 | C12: =1*1*'SEM Weights'!$C$9 -> 0.38 | D12: =1*2*'SEM Weights'!$C$9 -> 0.76 | E12: =1*3*'SEM Weights'!$C$9 -> 1.14 | F12: =1*4*'SEM Weights'!$C$9 -> 1.52 | G12: =1*5*'SEM Weights'!$C$9 -> 1.9 | H12: =1*5*'SEM Weights'!$C$9 -> 1.9

Sheet Project Analysis
A2: Top 30 Highest-Risk Projects | β=0.38
A3: High=25 projects | Max ARS=7.6
A5: Rank | B5: ID | C5: Institution | D5: Project Name | E5: P | F5: I | G5: β | H5: ARS | I5: Priority | J5: PM? | K5: RM? | L5: Complexity | M5: Status | N5: IS Score
A6: 1 | B6: P014 | C6: RPI | D6: Laboratory Information Managem | E6: 4 | F6: 5 | G6: ='SEM Weights'!$C$9 -> 0.38 | H6: =E6*F6*'SEM Weights'!$C$9 -> 7.6 | I6: =IF(H6>12,"Critical",IF(H6>=6,"High",IF(H6>=3,"Moderate","Low"))) -> High | J6: Yes | K6: Yes | L6: Low | M6: Delayed | N6: 3.33
A7: 2 | B7: P141 | C7: RPI | D7: Authentication | E7: 4 | F7: 5 | G7: ='SEM Weights'!$C$9 -> 0.38 | H7: =E7*F7*'SEM Weights'!$C$9 -> 7.6 | I7: =IF(H7>12,"Critical",IF(H7>=6,"High",IF(H7>=3,"Moderate","Low"))) -> High | J7: Yes | K7: Yes | L7: Medium | M7: Successful | N7: 4
A8: 3 | B8: P160 | C8: RPI | D8: Customer communication platfor | E8: 5 | F8: 4 | G8: ='SEM Weights'!$C$9 -> 0.38 | H8: =E8*F8*'SEM Weights'!$C$9 -> 7.6 | I8: =IF(H8>12,"Critical",IF(H8>=6,"High",IF(H8>=3,"Moderate","Low"))) -> High | J8: Yes | K8: Yes | L8: High | M8: Successful | N8: 4.33
A9: 4 | B9: P118 | C9: RPI | D9: Mathematical Modeling and Anal | E9: 4 | F9: 5 | G9: ='SEM Weights'!$C$9 -> 0.38 | H9: =E9*F9*'SEM Weights'!$C$9 -> 7.6 | I9: =IF(H9>12,"Critical",IF(H9>=6,"High",IF(H9>=3,"Moderate","Low"))) -> High | J9: Yes | K9: Yes | L9: High | M9: Successful | N9: 3.67
A10: 5 | B10: P048 | C10: RPI | D10: Student Government system for | E10: 4 | F10: 4 | G10: ='SEM Weights'!$C$9 -> 0.38 | H10: =E10*F10*'SEM Weights'!$C$9 -> 6.08 | I10: =IF(H10>12,"Critical",IF(H10>=6,"High",IF(H10>=3,"Moderate","Low"))) -> High | J10: Yes | K10: No | L10: Medium | M10: Delayed | N10: 2.67
A11: 6 | B11: P079 | C11: RPI | D11: Monitoring and communication t | E11: 4 | F11: 4 | G11: ='SEM Weights'!$C$9 -> 0.38 | H11: =E11*F11*'SEM Weights'!$C$9 -> 6.08 | I11: =IF(H11>12,"Critical",IF(H11>=6,"High",IF(H11>=3,"Moderate","Low"))) -> High | J11: Yes | K11: Yes | L11: Low | M11: Delayed | N11: 3.33
A12: 7 | B12: P102 | C12: RPI | D12: Imaging and Document Managemen | E12: 4 | F12: 4 | G12: ='SEM Weights'!$C$9 -> 0.38 | H12: =E12*F12*'SEM Weights'!$C$9 -> 6.08 | I12: =IF(H12>12,"Critical",IF(H12>=6,"High",IF(H12>=3,"Moderate","Low"))) -> High | J12: Yes | K12: Yes | L12: High | M12: Successful | N12: 3.67
A13: 8 | B13: P146 | C13: RPI | D13: Hosting of campus websites | E13: 4 | F13: 4 | G13: ='SEM Weights'!$C$9 -> 0.38 | H13: =E13*F13*'SEM Weights'!$C$9 -> 6.08 | I13: =IF(H13>12,"Critical",IF(H13>=6,"High",IF(H13>=3,"Moderate","Low"))) -> High | J13: Yes | K13: Yes | L13: Medium | M13: Delayed | N13: 3
A14: 9 | B14: P149 | C14: RPI | D14: Mail Authenticated Transport | E14: 4 | F14: 4 | G14: ='SEM Weights'!$C$9 -> 0.38 | H14: =E14*F14*'SEM Weights'!$C$9 -> 6.08 | I14: =IF(H14>12,"Critical",IF(H14>=6,"High",IF(H14>=3,"Moderate","Low"))) -> High | J14: No | K14: Yes | L14: High | M14: Delayed | N14: 3
A15: 10 | B15: P125 | C15: RPI | D15: Microsoft Office Tools/Campus | E15: 4 | F15: 4 | G15: ='SEM Weights'!$C$9 -> 0.38 | H15: =E15*F15*'SEM Weights'!$C$9 -> 6.08 | I15: =IF(H15>12,"Critical",IF(H15>=6,"High",IF(H15>=3,"Moderate","Low"))) -> High | J15: Yes | K15: Yes | L15: Medium | M15: Successful | N15: 5
A16: 11 | B16: P121 | C16: RPI | D16: Institutional Research complia | E16: 4 | F16: 4 | G16: ='SEM Weights'!$C$9 -> 0.38 | H16: =E16*F16*'SEM Weights'!$C$9 -> 6.08 | I16: =IF(H16>12,"Critical",IF(H16>=6,"High",IF(H16>=3,"Moderate","Low"))) -> High | J16: Yes | K16: Yes | L16: Medium | M16: Successful | N16: 3.67
A17: 12 | B17: P120 | C17: RPI | D17: Web Streaming and Cataloging P | E17: 4 | F17: 4 | G17: ='SEM Weights'!$C$9 -> 0.38 | H17: =E17*F17*'SEM Weights'!$C$9 -> 6.08 | I17: =IF(H17>12,"Critical",IF(H17>=6,"High",IF(H17>=3,"Moderate","Low"))) -> High | J17: No | K17: Yes | L17: Medium | M17: Delayed | N17: 3.33
... A33: 28 | B33: P110 | C33: RPI | D33: Procure-to-Pay; OSCAR: Workflo | E33: 5 | F33: 3 | G33: ='SEM Weights'!$C$9 -> 0.38 | H33: =E33*F33*'SEM Weights'!$C$9 -> 5.7 | I33: =IF(H33>12,"Critical",IF(H33>=6,"High",IF(H33>=3,"Moderate","Low"))) -> Moderate | J33: Yes | K33: Yes | L33: Low | M33: Successful | N33: 3.67
A34: 29 | B34: P004 | C34: RPI | E34: 3 | F34: 4 | G34: ='SEM Weights'!$C$9 -> 0.38 | H34: =E34*F34*'SEM Weights'!$C$9 -> 4.56 | I34: =IF(H34>12,"Critical",IF(H34>=6,"High",IF(H34>=3,"Moderate","Low"))) -> Moderate | J34: Yes | K34: No | L34: Low | M34: Delayed | N34: 3
A35: 30 | B35: P024 | C35: RPI | D35: Infrastructure as a Service | E35: 3 | F35: 4 | G35: ='SEM Weights'!$C$9 -> 0.38 | H35: =E35*F35*'SEM Weights'!$C$9 -> 4.56 | I35: =IF(H35>12,"Critical",IF(H35>=6,"High",IF(H35>=3,"Moderate","Low"))) -> Moderate | J35: No | K35: Yes | L35: Medium | M35: Successful | N35: 3.67

Sheet SEM Weights
A2: Path Coefficients — β Weight Reference
A3: β(RM→IS)=0.38 is the ARS weight. Update C9 after AMOS run to cascade all ARS scores.
B5: ✓ β=0.38 (RM→IS from PLS-SEM/AMOS). ARS = P × I × 0.38.
A7: Path | B7: H | C7: β | D7: SE | E7: t | F7: p-value | G7: 95% CI | H7: Decision
A8: PM → IS | B8: H1 | C8: 0.143 | D8: 0.066 | E8: 2.151 | F8: p=0.0327 | G8: — | H8: Supported ✓
A9: RM → IS ★ | B9: H3 | C9: 0.38 | D9: 0.066 | E9: 5.721 | F9: p<0.001 | G9: — | H9: Supported ✓ ★ (ARS β)
A10: PM → RM | B10: — | C10: 0.227 | D10: 0.07 | E10: 3.262 | F10: p=0.0013 | G10: — | H10: Significant
A11: Indirect PM→RM→IS | B11: H2 | C11: ='SEM Weights'!C10*'SEM Weights'!$C$9 -> 0.08626 | D11: — | E11: — | F11: — | G11: [0.0287,0.1484] | H11: Supported ✓ (partial)
B15: ARS FORMULA: ARS = P × I × β (edit β in cell C9 — all ARS scores update automatically)

Sheet Formula Derivation
A2: How β=0.38 Was Derived — 9-Step Proof
A3: Every formula used to derive the ARS weight from 197 institutional projects.
A5: Step | B5: Title | C5: Formula | D5: Result | E5: Why this matters
A6: 1 | B6: Build composites | C6: PM=mean(PM1-3) | RM=mean(RM1-3) | IS=mean(IS1-3) | D6: PM=3.09 RM=3.081 IS=3.181 | E6: Mean of 3 reflective indicators per construct
A7: 2 | B7: Standardize | C7: z=(x-mean)/SD for each composite | D7: mean=0, SD=1 | E7: Makes β directly comparable across constructs
A8: 3 | B8: Correlations | C8: r(RM_z, IS_z) — strongest pairwise | D8: r(RM,IS)≈0.41 | E8: Inputs to OLS regression
A9: 4 | B9: Design matrix | C9: X=[1|PM_z|RM_z] (197×3 matrix) | D9: Normal equations | E9: β=(XᵀX)⁻¹·Xᵀy
A10: 5 | B10: Solve normal eqs | C10: β=(XᵀX)⁻¹·Xᵀy → β₀≈0, β₁=PM→IS, β₂=RM→IS | D10: β₂=0.38 ← ARS WEIGHT | E10: β₂ is RM→IS standardized coefficient
A11: 6 | B11: Model fit | C11: R²=1-SS_res/SS_tot | Adj.R²=1-(1-R²)(N-1)/(N-3) | D11: R²=0.189 Adj.R²=0.181 | E11: PM+RM explain 18.9% of IS variance
A12: 7 | B12: Standard error | C12: SE(β₂)=√(MSE×(XᵀX)⁻¹[2,2]) | D12: SE=0.066 | E12: Needed for t-test and CI
A13: 8 | B13: t-test | C13: t=β₂/SE | p=2×P(T>|t|) df=N-3={N-3} | D13: t=5.721 p<0.001 | E13: Highly significant — β is stable and reliable
A14: 9 | B14: ARS formula | C14: ARS = P × I × β₂ | D14: ARS = P × I × 0.38 | E14: Empirical causal weight replaces arbitrary expert estimates
