Workbook

Sheet Dashboard
A2: EdTech Implementation Risk Intelligence System (EIIS)
A3: SEM-Weighted Risk Prioritization Tool | N = 195 Projects | RPI & LA Tech | ARS = P × I × β
B6: Total Projects | E6: Critical + High | H6: High | K6: Moderate | N6: Low
B7: 195 | E7: 28 | H7: 28 | K7: 93 | N7: 74
B10: Current SEM β Weights (Update after AMOS run)
B11: PM → IS β = 0.31 | D11: RM → IS β = 0.53 | F11: PM → RM γ = 0.62
B14: HOW TO USE THIS TOOL
B15: 1 | C15: SEM Weights tab — update β values with your final IBM AMOS output. All ARS scores recalculate instantly.
B16: 2 | C16: Risk Register tab — all 195 real projects pre-loaded with live ARS scores, priorities, and recommended actions.
B17: 3 | C17: Add new risks in blank rows at the bottom. Select Category from dropdown; P and I scores auto-pull from your data.
B18: 4 | C18: Risk Heatmap tab — view the ARS matrix showing score ranges for every P × I combination at each β weight.
B19: 5 | C19: Project Analysis tab — filter and review individual project risk profiles sorted by ARS score.
B22: PRIORITY SUMMARY — ALL 195 PROJECTS
B23: Priority | D23: ARS Range | F23: Count (%) | H23: Dominant Pattern | K23: Recommended Response
B24: Critical | D24: ARS > 12 | F24: 0 (0.0%) | H24: — | K24: No Critical risks in current dataset
B25: High | D25: 6.0–12.0 | F25: 28 (14.4%) | H25: All Delayed outcomes; High complexity | K25: Active mitigation required; assign risk owners
B26: Moderate | D26: 3.0–6.0 | F26: 93 (47.7%) | H26: Mix of Delayed and Successful | K26: Periodic monitoring; contingency planning
B27: Low | D27: < 3.0 | F27: 74 (37.9%) | H27: Majority Successful outcomes | K27: Accept with monitoring; review at completion

Sheet SEM Weights
A2: SEM-Derived Construct Weights — IBM AMOS Output
A3: Blue cells = user inputs. Update β values with your final AMOS path coefficients. All ARS calculations in the Risk Register update automatically.
B5: ⚠ Placeholder β values shown. Replace with actual AMOS standardized path coefficients after running your SEM.
B7: Construct | C7: Path | D7: β Coefficient | E7: Std. Error | F7: t-value | G7: p-value | H7: 95% CI | I7: Supported?
B8: Project Management (PM) | C8: PM → IS (Direct) | D8: 0.31 | E8: 0.07 | F8: 4.43 | G8: < 0.001 | H8: [0.17, 0.45] | I8: Yes
B9: Risk Management (RM) | C9: RM → IS (Direct) | D9: 0.53 | E9: 0.08 | F9: 5.5 | G9: < 0.001 | H9: [0.28, 0.60] | I9: Yes
B10: PM (Mediated) | C10: PM → RM → IS | D10: 0.27 | E10: 0.06 | F10: 4.5 | G10: < 0.001 | H10: [0.15, 0.41] | I10: Yes
B11: Project Management | C11: PM → RM | D11: 0.62 | E11: 0.09 | F11: 6.89 | G11: < 0.001 | H11: [0.53, 0.80] | I11: Yes
B15: WEIGHTS APPLIED IN ARS FORMULA — PULL FROM ABOVE
B16: PM-category risks (β = PM → IS) | F16: =C8 | G16: Used as weight for all Project Management risks in register
B17: RM-category risks (β = RM → IS) | F17: =C9 | G17: Used as weight for all Risk Management risks in register — THIS IS YOUR ARS β

Sheet Risk Register
A2: Risk Register — All 195 EdTech Projects | ARS-Weighted Priorities
A3: ARS = P × I × β | β weights live from SEM Weights sheet | Sorted by ARS (highest first) | Blue cells = user inputs
A5: Total | B5: Critical | C5: High | D5: Moderate | E5: Low | F5: Avg ARS
A6: =COUNTA(A8:A300)-COUNTBLANK(A8:A300) | B6: =COUNTIF(J8:J300,"Critical") | C6: =COUNTIF(J8:J300,"High") | D6: =COUNTIF(J8:J300,"Moderate") | E6: =COUNTIF(J8:J300,"Low") | F6: =ROUND(AVERAGE(I8:I300),3)
A7: Project ID | B7: Institution | C7: Project Name | D7: Risk Category | E7: P (Prob) 1–5 | F7: I (Impact) 1–5 | G7: β Weight (SEM) | H7: P × I | I7: ARS (P×I×β) | J7: Priority Tier | K7: Recommended Action | L7: PM Used | M7: Outcome
A8: P195 | B8: LA Tech | C8: Workday Student | D8: Risk Management | E8: 4.27 | F8: 5 | G8: =IF(D8="Project Management",'SEM Weights'!$C$8,IF(D8="Risk Management",'SEM Weights'!$C$9,0.30)) | H8: =E8*F8 | I8: 9.394 | J8: =IF(I8="","",IF(I8>12,"Critical",IF(I8>=6,"High",IF(I8>=3,"Moderate","Low")))) | K8: =IF(J8="Critical","Immediate mitigation — assign dedicated risk owner now",IF(J8="High","Active mitigation planning required; include in project risk register",IF(J8="Moderate","Periodic monitoring; develop contingency plan at next milestone",IF(J8="Low","Accept with monitoring; review at project completion","")))) | L8: Yes | M8: Delayed
A9: P053 | B9: RPI | C9: Network services | D9: Risk Management | E9: 4.64 | F9: 4.25 | G9: =IF(D9="Project Management",'SEM Weights'!$C$8,IF(D9="Risk Management",'SEM Weights'!$C$9,0.30)) | H9: =E9*F9 | I9: 8.677 | J9: =IF(I9="","",IF(I9>12,"Critical",IF(I9>=6,"High",IF(I9>=3,"Moderate","Low")))) | K9: =IF(J9="Critical","Immediate mitigation — assign dedicated risk owner now",IF(J9="High","Active mitigation planning required; include in project risk register",IF(J9="Moderate","Periodic monitoring; develop contingency plan at next milestone",IF(J9="Low","Accept with monitoring; review at project completion","")))) | L9: Yes | M9: Delayed
A10: P107 | B10: RPI | C10: Inventions and patents | D10: Risk Management | E10: 3.91 | F10: 5 | G10: =IF(D10="Project Management",'SEM Weights'!$C$8,IF(D10="Risk Management",'SEM Weights'!$C$9,0.30)) | H10: =E10*F10 | I10: 8.602 | J10: =IF(I10="","",IF(I10>12,"Critical",IF(I10>=6,"High",IF(I10>=3,"Moderate","Low")))) | K10: =IF(J10="Critical","Immediate mitigation — assign dedicated risk owner now",IF(J10="High","Active mitigation planning required; include in project risk register",IF(J10="Moderate","Periodic monitoring; develop contingency plan at next milestone",IF(J10="Low","Accept with monitoring; review at project completion","")))) | L10: No | M10: Delayed
A11: P155 | B11: RPI | C11: Email Spam filter | D11: Risk Management | E11: 4.27 | F11: 4.5 | G11: =IF(D11="Project Management",'SEM Weights'!$C$8,IF(D11="Risk Management",'SEM Weights'!$C$9,0.30)) | H11: =E11*F11 | I11: 8.455 | J11: =IF(I11="","",IF(I11>12,"Critical",IF(I11>=6,"High",IF(I11>=3,"Moderate","Low")))) | K11: =IF(J11="Critical","Immediate mitigation — assign dedicated risk owner now",IF(J11="High","Active mitigation planning required; include in project risk register",IF(J11="Moderate","Periodic monitoring; develop contingency plan at next milestone",IF(J11="Low","Accept with monitoring; review at project completion","")))) | L11: Yes | M11: Delayed
A12: P049 | B12: RPI | C12: Backups | D12: Risk Management | E12: 3.91 | F12: 4.75 | G12: =IF(D12="Project Management",'SEM Weights'!$C$8,IF(D12="Risk Management",'SEM Weights'!$C$9,0.30)) | H12: =E12*F12 | I12: 8.172 | J12: =IF(I12="","",IF(I12>12,"Critical",IF(I12>=6,"High",IF(I12>=3,"Moderate","Low")))) | K12: =IF(J12="Critical","Immediate mitigation — assign dedicated risk owner now",IF(J12="High","Active mitigation planning required; include in project risk register",IF(J12="Moderate","Periodic monitoring; develop contingency plan at next milestone",IF(J12="Low","Accept with monitoring; review at project completion","")))) | L12: Yes | M12: Delayed
A13: P010 | B13: RPI | C13: Parking Management System | D13: Risk Management | E13: 4.27 | F13: 4.25 | G13: =IF(D13="Project Management",'SEM Weights'!$C$8,IF(D13="Risk Management",'SEM Weights'!$C$9,0.30)) | H13: =E13*F13 | I13: 7.985 | J13: =IF(I13="","",IF(I13>12,"Critical",IF(I13>=6,"High",IF(I13>=3,"Moderate","Low")))) | K13: =IF(J13="Critical","Immediate mitigation — assign dedicated risk owner now",IF(J13="High","Active mitigation planning required; include in project risk register",IF(J13="Moderate","Periodic monitoring; develop contingency plan at next milestone",IF(J13="Low","Accept with monitoring; review at project completion","")))) | L13: No | M13: Delayed
A14: P076 | B14: RPI | C14: Payment processing Software (check printing) | D14: Risk Management | E14: 3.55 | F14: 5 | G14: =IF(D14="Project Management",'SEM Weights'!$C$8,IF(D14="Risk Management",'SEM Weights'!$C$9,0.30)) | H14: =E14*F14 | I14: 7.81 | J14: =IF(I14="","",IF(I14>12,"Critical",IF(I14>=6,"High",IF(I14>=3,"Moderate","Low")))) | K14: =IF(J14="Critical","Immediate mitigation — assign dedicated risk owner now",IF(J14="High","Active mitigation planning required; include in project risk register",IF(J14="Moderate","Periodic monitoring; develop contingency plan at next milestone",IF(J14="Low","Accept with monitoring; review at project completion","")))) | L14: Yes | M14: Delayed
A15: P136 | B15: RPI | C15: Interlibrary loan and document delivery syste | D15: Risk Management | E15: 3.55 | F15: 5 | G15: =IF(D15="Project Management",'SEM Weights'!$C$8,IF(D15="Risk Management",'SEM Weights'!$C$9,0.30)) | H15: =E15*F15 | I15: 7.81 | J15: =IF(I15="","",IF(I15>12,"Critical",IF(I15>=6,"High",IF(I15>=3,"Moderate","Low")))) | K15: =IF(J15="Critical","Immediate mitigation — assign dedicated risk owner now",IF(J15="High","Active mitigation planning required; include in project risk register",IF(J15="Moderate","Periodic monitoring; develop contingency plan at next milestone",IF(J15="Low","Accept with monitoring; review at project completion","")))) | L15: No | M15: Delayed
A16: P122 | B16: RPI | C16: Package Tracking System | D16: Risk Management | E16: 3.55 | F16: 5 | G16: =IF(D16="Project Management",'SEM Weights'!$C$8,IF(D16="Risk Management",'SEM Weights'!$C$9,0.30)) | H16: =E16*F16 | I16: 7.81 | J16: =IF(I16="","",IF(I16>12,"Critical",IF(I16>=6,"High",IF(I16>=3,"Moderate","Low")))) | K16: =IF(J16="Critical","Immediate mitigation — assign dedicated risk owner now",IF(J16="High","Active mitigation planning required; include in project risk register",IF(J16="Moderate","Periodic monitoring; develop contingency plan at next milestone",IF(J16="Low","Accept with monitoring; review at project completion","")))) | L16: Yes | M16: Delayed
A17: P142 | B17: RPI | C17: Data Warehouse Business Intelligence and Anal | D17: Risk Management | E17: 3.91 | F17: 4.5 | G17: =IF(D17="Project Management",'SEM Weights'!$C$8,IF(D17="Risk Management",'SEM Weights'!$C$9,0.30)) | H17: =E17*F17 | I17: 7.742 | J17: =IF(I17="","",IF(I17>12,"Critical",IF(I17>=6,"High",IF(I17>=3,"Moderate","Low")))) | K17: =IF(J17="Critical","Immediate mitigation — assign dedicated risk owner now",IF(J17="High","Active mitigation planning required; include in project risk register",IF(J17="Moderate","Periodic monitoring; develop contingency plan at next milestone",IF(J17="Low","Accept with monitoring; review at project completion","")))) | L17: Yes | M17: Delayed
A18: P110 | B18: RPI | C18: Intellectual Property | D18: Risk Management | E18: 5 | F18: 3.5 | G18: =IF(D18="Project Management",'SEM Weights'!$C$8,IF(D18="Risk Management",'SEM Weights'!$C$9,0.30)) | H18: =E18*F18 | I18: 7.7 | J18: =IF(I18="","",IF(I18>12,"Critical",IF(I18>=6,"High",IF(I18>=3,"Moderate","Low")))) | K18: =IF(J18="Critical","Immediate mitigation — assign dedicated risk owner now",IF(J18="High","Active mitigation planning required; include in project risk register",IF(J18="Moderate","Periodic monitoring; develop contingency plan at next milestone",IF(J18="Low","Accept with monitoring; review at project completion","")))) | L18: Yes | M18: Failed
A19: P041 | B19: RPI | C19: Wireless network management | D19: Risk Management | E19: 3.55 | F19: 4.75 | G19: =IF(D19="Project Management",'SEM Weights'!$C$8,IF(D19="Risk Management",'SEM Weights'!$C$9,0.30)) | H19: =E19*F19 | I19: 7.42 | J19: =IF(I19="","",IF(I19>12,"Critical",IF(I19>=6,"High",IF(I19>=3,"Moderate","Low")))) | K19: =IF(J19="Critical","Immediate mitigation — assign dedicated risk owner now",IF(J19="High","Active mitigation planning required; include in project risk register",IF(J19="Moderate","Periodic monitoring; develop contingency plan at next milestone",IF(J19="Low","Accept with monitoring; review at project completion","")))) | L19: Yes | M19: Delayed
... A85: P187 | B85: RPI | C85: Chemical Tracking System | D85: Organizational Readiness | E85: 2.09 | F85: 4.25 | G85: =IF(D85="Project Management",'SEM Weights'!$C$8,IF(D85="Risk Management",'SEM Weights'!$C$9,0.30)) | H85: =E85*F85 | I85: 3.908 | J85: =IF(I85="","",IF(I85>12,"Critical",IF(I85>=6,"High",IF(I85>=3,"Moderate","Low")))) | K85: =IF(J85="Critical","Immediate mitigation — assign dedicated risk owner now",IF(J85="High","Active mitigation planning required; include in project risk register",IF(J85="Moderate","Periodic monitoring; develop contingency plan at next milestone",IF(J85="Low","Accept with monitoring; review at project completion","")))) | L85: Yes | M85: Successful
A86: P081 | B86: RPI | D86: Risk Management | E86: 3.55 | F86: 2.5 | G86: =IF(D86="Project Management",'SEM Weights'!$C$8,IF(D86="Risk Management",'SEM Weights'!$C$9,0.30)) | H86: =E86*F86 | I86: 3.905 | J86: =IF(I86="","",IF(I86>12,"Critical",IF(I86>=6,"High",IF(I86>=3,"Moderate","Low")))) | K86: =IF(J86="Critical","Immediate mitigation — assign dedicated risk owner now",IF(J86="High","Active mitigation planning required; include in project risk register",IF(J86="Moderate","Periodic monitoring; develop contingency plan at next milestone",IF(J86="Low","Accept with monitoring; review at project completion","")))) | L86: Yes | M86: Delayed
A87: P021 | B87: RPI | C87: Public Safety Voice Recording System | D87: Risk Management | E87: 3.55 | F87: 2.5 | G87: =IF(D87="Project Management",'SEM Weights'!$C$8,IF(D87="Risk Management",'SEM Weights'!$C$9,0.30)) | H87: =E87*F87 | I87: 3.905 | J87: =IF(I87="","",IF(I87>12,"Critical",IF(I87>=6,"High",IF(I87>=3,"Moderate","Low")))) | K87: =IF(J87="Critical","Immediate mitigation — assign dedicated risk owner now",IF(J87="High","Active mitigation planning required; include in project risk register",IF(J87="Moderate","Periodic monitoring; develop contingency plan at next milestone",IF(J87="Low","Accept with monitoring; review at project completion","")))) | L87: Yes | M87: Delayed
A88: P105 | B88: RPI | C88: Space Management | D88: Risk Management | E88: 3.55 | F88: 2.5 | G88: =IF(D88="Project Management",'SEM Weights'!$C$8,IF(D88="Risk Management",'SEM Weights'!$C$9,0.30)) | H88: =E88*F88 | I88: 3.905 | J88: =IF(I88="","",IF(I88>12,"Critical",IF(I88>=6,"High",IF(I88>=3,"Moderate","Low")))) | K88: =IF(J88="Critical","Immediate mitigation — assign dedicated risk owner now",IF(J88="High","Active mitigation planning required; include in project risk register",IF(J88="Moderate","Periodic monitoring; develop contingency plan at next milestone",IF(J88="Low","Accept with monitoring; review at project completion","")))) | L88: Yes | M88: Delayed
A89: P147 | B89: RPI | C89: Postal System | D89: Risk Management | E89: 3.55 | F89: 2.5 | G89: =IF(D89="Project Management",'SEM Weights'!$C$8,IF(D89="Risk Management",'SEM Weights'!$C$9,0.30)) | H89: =E89*F89 | I89: 3.905 | J89: =IF(I89="","",IF(I89>12,"Critical",IF(I89>=6,"High",IF(I89>=3,"Moderate","Low")))) | K89: =IF(J89="Critical","Immediate mitigation — assign dedicated risk owner now",IF(J89="High","Active mitigation planning required; include in project risk register",IF(J89="Moderate","Periodic monitoring; develop contingency plan at next milestone",IF(J89="Low","Accept with monitoring; review at project completion","")))) | L89: No | M89: Delayed
A90: P082 | B90: RPI | C90: View/Purchase course materials from the LMS V | D90: Risk Management | E90: 3.91 | F90: 2.25 | G90: =IF(D90="Project Management",'SEM Weights'!$C$8,IF(D90="Risk Management",'SEM Weights'!$C$9,0.30)) | H90: =E90*F90 | I90: 3.871 | J90: =IF(I90="","",IF(I90>12,"Critical",IF(I90>=6,"High",IF(I90>=3,"Moderate","Low")))) | K90: =IF(J90="Critical","Immediate mitigation — assign dedicated risk owner now",IF(J90="High","Active mitigation planning required; include in project risk register",IF(J90="Moderate","Periodic monitoring; develop contingency plan at next milestone",IF(J90="Low","Accept with monitoring; review at project completion","")))) | L90: No | M90: Delayed
A91: P138 | B91: RPI | C91: Card Access ID Access; Campus Security – door | D91: Organizational Readiness | E91: 3.18 | F91: 2.75 | G91: =IF(D91="Project Management",'SEM Weights'!$C$8,IF(D91="Risk Management",'SEM Weights'!$C$9,0.30)) | H91: =E91*F91 | I91: 3.848 | J91: =IF(I91="","",IF(I91>12,"Critical",IF(I91>=6,"High",IF(I91>=3,"Moderate","Low")))) | K91: =IF(J91="Critical","Immediate mitigation — assign dedicated risk owner now",IF(J91="High","Active mitigation planning required; include in project risk register",IF(J91="Moderate","Periodic monitoring; develop contingency plan at next milestone",IF(J91="Low","Accept with monitoring; review at project completion","")))) | L91: No | M91: Delayed
A92: P184 | B92: RPI | C92: Online meal ordering system | D92: Organizational Readiness | E92: 3.18 | F92: 2.75 | G92: =IF(D92="Project Management",'SEM Weights'!$C$8,IF(D92="Risk Management",'SEM Weights'!$C$9,0.30)) | H92: =E92*F92 | I92: 3.848 | J92: =IF(I92="","",IF(I92>12,"Critical",IF(I92>=6,"High",IF(I92>=3,"Moderate","Low")))) | K92: =IF(J92="Critical","Immediate mitigation — assign dedicated risk owner now",IF(J92="High","Active mitigation planning required; include in project risk register",IF(J92="Moderate","Periodic monitoring; develop contingency plan at next milestone",IF(J92="Low","Accept with monitoring; review at project completion","")))) | L92: Yes | M92: Delayed
A93: P084 | B93: RPI | C93: View course material from the course catalog | D93: Organizational Readiness | E93: 3.18 | F93: 2.75 | G93: =IF(D93="Project Management",'SEM Weights'!$C$8,IF(D93="Risk Management",'SEM Weights'!$C$9,0.30)) | H93: =E93*F93 | I93: 3.848 | J93: =IF(I93="","",IF(I93>12,"Critical",IF(I93>=6,"High",IF(I93>=3,"Moderate","Low")))) | K93: =IF(J93="Critical","Immediate mitigation — assign dedicated risk owner now",IF(J93="High","Active mitigation planning required; include in project risk register",IF(J93="Moderate","Periodic monitoring; develop contingency plan at next milestone",IF(J93="Low","Accept with monitoring; review at project completion","")))) | L93: Yes | M93: Delayed
A94: P028 | B94: RPI | C94: LMS (Learning Mgmt System) | D94: Organizational Readiness | E94: 3.18 | F94: 2.75 | G94: =IF(D94="Project Management",'SEM Weights'!$C$8,IF(D94="Risk Management",'SEM Weights'!$C$9,0.30)) | H94: =E94*F94 | I94: 3.848 | J94: =IF(I94="","",IF(I94>12,"Critical",IF(I94>=6,"High",IF(I94>=3,"Moderate","Low")))) | K94: =IF(J94="Critical","Immediate mitigation — assign dedicated risk owner now",IF(J94="High","Active mitigation planning required; include in project risk register",IF(J94="Moderate","Periodic monitoring; develop contingency plan at next milestone",IF(J94="Low","Accept with monitoring; review at project completion","")))) | L94: No | M94: Delayed
A95: P079 | B95: RPI | C95: Load Balancing | D95: Organizational Readiness | E95: 3.18 | F95: 2.75 | G95: =IF(D95="Project Management",'SEM Weights'!$C$8,IF(D95="Risk Management",'SEM Weights'!$C$9,0.30)) | H95: =E95*F95 | I95: 3.848 | J95: =IF(I95="","",IF(I95>12,"Critical",IF(I95>=6,"High",IF(I95>=3,"Moderate","Low")))) | K95: =IF(J95="Critical","Immediate mitigation — assign dedicated risk owner now",IF(J95="High","Active mitigation planning required; include in project risk register",IF(J95="Moderate","Periodic monitoring; develop contingency plan at next milestone",IF(J95="Low","Accept with monitoring; review at project completion","")))) | L95: Yes | M95: Delayed
A96: P120 | B96: RPI | C96: Institutional Research compliance management | D96: Organizational Readiness | E96: 3.18 | F96: 2.75 | G96: =IF(D96="Project Management",'SEM Weights'!$C$8,IF(D96="Risk Management",'SEM Weights'!$C$9,0.30)) | H96: =E96*F96 | I96: 3.848 | J96: =IF(I96="","",IF(I96>12,"Critical",IF(I96>=6,"High",IF(I96>=3,"Moderate","Low")))) | K96: =IF(J96="Critical","Immediate mitigation — assign dedicated risk owner now",IF(J96="High","Active mitigation planning required; include in project risk register",IF(J96="Moderate","Periodic monitoring; develop contingency plan at next milestone",IF(J96="Low","Accept with monitoring; review at project completion","")))) | L96: Yes | M96: Delayed
A97: P080 | B97: RPI | C97: Process Management | D97: Organizational Readiness | E97: 3.18 | F97: 2.75 | G97: =IF(D97="Project Management",'SEM Weights'!$C$8,IF(D97="Risk Management",'SEM Weights'!$C$9,0.30)) | H97: =E97*F97 | I97: 3.848 | J97: =IF(I97="","",IF(I97>12,"Critical",IF(I97>=6,"High",IF(I97>=3,"Moderate","Low")))) | K97: =IF(J97="Critical","Immediate mitigation — assign dedicated risk owner now",IF(J97="High","Active mitigation planning required; include in project risk register",IF(J97="Moderate","Periodic monitoring; develop contingency plan at next milestone",IF(J97="Low","Accept with monitoring; review at project completion","")))) | L97: Yes | M97: Delayed
A98: P185 | B98: RPI | C98: Project management tool | D98: Organizational Readiness | E98: 2.45 | F98: 3.5 | G98: =IF(D98="Project Management",'SEM Weights'!$C$8,IF(D98="Risk Management",'SEM Weights'!$C$9,0.30)) | H98: =E98*F98 | I98: 3.773 | J98: =IF(I98="","",IF(I98>12,"Critical",IF(I98>=6,"High",IF(I98>=3,"Moderate","Low")))) | K98: =IF(J98="Critical","Immediate mitigation — assign dedicated risk owner now",IF(J98="High","Active mitigation planning required; include in project risk register",IF(J98="Moderate","Periodic monitoring; develop contingency plan at next milestone",IF(J98="Low","Accept with monitoring; review at project completion","")))) | L98: Yes | M98: Successful
... A198: P047 | B198: RPI | C198: Student Government system for club budgeting | D198: Project Management | E198: 2.09 | F198: 1 | G198: =IF(D198="Project Management",'SEM Weights'!$C$8,IF(D198="Risk Management",'SEM Weights'!$C$9,0.30)) | H198: =E198*F198 | I198: 0.92 | J198: =IF(I198="","",IF(I198>12,"Critical",IF(I198>=6,"High",IF(I198>=3,"Moderate","Low")))) | K198: =IF(J198="Critical","Immediate mitigation — assign dedicated risk owner now",IF(J198="High","Active mitigation planning required; include in project risk register",IF(J198="Moderate","Periodic monitoring; develop contingency plan at next milestone",IF(J198="Low","Accept with monitoring; review at project completion","")))) | L198: Yes | M198: Successful
A199: P093 | B199: RPI | D199: Project Management | E199: 2.09 | F199: 1 | G199: =IF(D199="Project Management",'SEM Weights'!$C$8,IF(D199="Risk Management",'SEM Weights'!$C$9,0.30)) | H199: =E199*F199 | I199: 0.92 | J199: =IF(I199="","",IF(I199>12,"Critical",IF(I199>=6,"High",IF(I199>=3,"Moderate","Low")))) | K199: =IF(J199="Critical","Immediate mitigation — assign dedicated risk owner now",IF(J199="High","Active mitigation planning required; include in project risk register",IF(J199="Moderate","Periodic monitoring; develop contingency plan at next milestone",IF(J199="Low","Accept with monitoring; review at project completion","")))) | L199: Yes | M199: Successful
A200: P146 | B200: RPI | C200: Print job management/accounting | D200: Project Management | E200: 1.36 | F200: 1.5 | G200: =IF(D200="Project Management",'SEM Weights'!$C$8,IF(D200="Risk Management",'SEM Weights'!$C$9,0.30)) | H200: =E200*F200 | I200: 0.898 | J200: =IF(I200="","",IF(I200>12,"Critical",IF(I200>=6,"High",IF(I200>=3,"Moderate","Low")))) | K200: =IF(J200="Critical","Immediate mitigation — assign dedicated risk owner now",IF(J200="High","Active mitigation planning required; include in project risk register",IF(J200="Moderate","Periodic monitoring; develop contingency plan at next milestone",IF(J200="Low","Accept with monitoring; review at project completion","")))) | L200: No | M200: Successful
A201: P156 | B201: RPI | C201: Development call campaign, RenExchange | D201: Project Management | E201: 1.36 | F201: 1.5 | G201: =IF(D201="Project Management",'SEM Weights'!$C$8,IF(D201="Risk Management",'SEM Weights'!$C$9,0.30)) | H201: =E201*F201 | I201: 0.898 | J201: =IF(I201="","",IF(I201>12,"Critical",IF(I201>=6,"High",IF(I201>=3,"Moderate","Low")))) | K201: =IF(J201="Critical","Immediate mitigation — assign dedicated risk owner now",IF(J201="High","Active mitigation planning required; include in project risk register",IF(J201="Moderate","Periodic monitoring; develop contingency plan at next milestone",IF(J201="Low","Accept with monitoring; review at project completion","")))) | L201: No | M201: Successful
A202: P176 | B202: RPI | C202: Budget Planning | D202: Project Management | E202: 1 | F202: 1.75 | G202: =IF(D202="Project Management",'SEM Weights'!$C$8,IF(D202="Risk Management",'SEM Weights'!$C$9,0.30)) | H202: =E202*F202 | I202: 0.77 | J202: =IF(I202="","",IF(I202>12,"Critical",IF(I202>=6,"High",IF(I202>=3,"Moderate","Low")))) | K202: =IF(J202="Critical","Immediate mitigation — assign dedicated risk owner now",IF(J202="High","Active mitigation planning required; include in project risk register",IF(J202="Moderate","Periodic monitoring; develop contingency plan at next milestone",IF(J202="Low","Accept with monitoring; review at project completion","")))) | L202: Yes | M202: Successful
A203: R196 | G203: =IF(D203="Project Management",'SEM Weights'!$C$8,IF(D203="Risk Management",'SEM Weights'!$C$9,0.30)) | H203: =IF(E203="","",E203*F203) | I203: =IF(E203="","",E203*F203*G203) | J203: =IF(I203="","",IF(I203>12,"Critical",IF(I203>=6,"High",IF(I203>=3,"Moderate","Low")))) | K203: =IF(J203="Critical","Immediate mitigation — assign dedicated risk owner now",IF(J203="High","Active mitigation planning required; include in project risk register",IF(J203="Moderate","Periodic monitoring; develop contingency plan at next milestone",IF(J203="Low","Accept with monitoring; review at project completion",""))))
A204: R197 | G204: =IF(D204="Project Management",'SEM Weights'!$C$8,IF(D204="Risk Management",'SEM Weights'!$C$9,0.30)) | H204: =IF(E204="","",E204*F204) | I204: =IF(E204="","",E204*F204*G204) | J204: =IF(I204="","",IF(I204>12,"Critical",IF(I204>=6,"High",IF(I204>=3,"Moderate","Low")))) | K204: =IF(J204="Critical","Immediate mitigation — assign dedicated risk owner now",IF(J204="High","Active mitigation planning required; include in project risk register",IF(J204="Moderate","Periodic monitoring; develop contingency plan at next milestone",IF(J204="Low","Accept with monitoring; review at project completion",""))))
A205: R198 | G205: =IF(D205="Project Management",'SEM Weights'!$C$8,IF(D205="Risk Management",'SEM Weights'!$C$9,0.30)) | H205: =IF(E205="","",E205*F205) | I205: =IF(E205="","",E205*F205*G205) | J205: =IF(I205="","",IF(I205>12,"Critical",IF(I205>=6,"High",IF(I205>=3,"Moderate","Low")))) | K205: =IF(J205="Critical","Immediate mitigation — assign dedicated risk owner now",IF(J205="High","Active mitigation planning required; include in project risk register",IF(J205="Moderate","Periodic monitoring; develop contingency plan at next milestone",IF(J205="Low","Accept with monitoring; review at project completion",""))))
A206: R199 | G206: =IF(D206="Project Management",'SEM Weights'!$C$8,IF(D206="Risk Management",'SEM Weights'!$C$9,0.30)) | H206: =IF(E206="","",E206*F206) | I206: =IF(E206="","",E206*F206*G206) | J206: =IF(I206="","",IF(I206>12,"Critical",IF(I206>=6,"High",IF(I206>=3,"Moderate","Low")))) | K206: =IF(J206="Critical","Immediate mitigation — assign dedicated risk owner now",IF(J206="High","Active mitigation planning required; include in project risk register",IF(J206="Moderate","Periodic monitoring; develop contingency plan at next milestone",IF(J206="Low","Accept with monitoring; review at project completion",""))))
...

Sheet Risk Heatmap
A2: Risk Heatmap — ARS Matrix by P × I × β
A3: Each cell = ARS value for that P × I combination at the given β weight. Colour = priority tier. Your dataset β = 0.53 (RM) and 0.31 (PM).
B6: PM Risks — Project Management (β = 0.31, from SEM Weights C8) | K6: RM Risks — Risk Management (β = 0.53, from SEM Weights C9) ← your ARS β
B7: P \ I → | C7: I = 1 | D7: I = 2 | E7: I = 3 | F7: I = 4 | G7: I = 5 | H7: Max ARS | K7: P \ I → | L7: I = 1 | M7: I = 2 | N7: I = 3 | O7: I = 4 | P7: I = 5 | Q7: Max ARS
B8: P = 5 | C8: 1.55 | D8: 3.1 | E8: 4.65 | F8: 6.2 | G8: 7.75 | H8: 7.75 | K8: P = 5 | L8: 2.2 | M8: 4.4 | N8: 6.6 | O8: 8.8 | P8: 11 | Q8: 11
B9: P = 4 | C9: 1.24 | D9: 2.48 | E9: 3.72 | F9: 4.96 | G9: 6.2 | H9: 6.2 | K9: P = 4 | L9: 1.76 | M9: 3.52 | N9: 5.28 | O9: 7.04 | P9: 8.8 | Q9: 8.8
B10: P = 3 | C10: 0.93 | D10: 1.86 | E10: 2.79 | F10: 3.72 | G10: 4.65 | H10: 4.65 | K10: P = 3 | L10: 1.32 | M10: 2.64 | N10: 3.96 | O10: 5.28 | P10: 6.6 | Q10: 6.6
B11: P = 2 | C11: 0.62 | D11: 1.24 | E11: 1.86 | F11: 2.48 | G11: 3.1 | H11: 3.1 | K11: P = 2 | L11: 0.88 | M11: 1.76 | N11: 2.64 | O11: 3.52 | P11: 4.4 | Q11: 4.4
B12: P = 1 | C12: 0.31 | D12: 0.62 | E12: 0.93 | F12: 1.24 | G12: 1.55 | H12: 1.55 | K12: P = 1 | L12: 0.53 | M12: 0.88 | N12: 1.32 | O12: 1.76 | P12: 2.2 | Q12: 2.2
B15: ACTUAL ARS DISTRIBUTION IN DATASET (N = 195)
B16: High (ARS 6–12): 28 projects (14.4%) | D16: Moderate (3–6): 93 projects (47.7%) | F16: Low (< 3): 74 projects (37.9%) | H16: Max ARS in data: 9.394 (P195 — Workday Student, LA Tech) | J16: Mean ARS: 3.805
B19: LEGEND
B20: Critical | D20: ARS > 12 | F20: No projects in current dataset at this tier
B21: High | D21: 6.0–12.0 | F21: 28 projects (14.4%) — all Delayed; assign risk owners now
B22: Moderate | D22: 3.0–6.0 | F22: 93 projects (47.7%) — active monitoring and contingency planning
B23: Low | D23: < 3.0 | F23: 74 projects (37.9%) — majority Successful; accept with monitoring

Sheet Project Analysis
A2: Project Analysis — Top 30 Highest ARS Projects
A3: Projects sorted by ARS score (highest risk first). Use this sheet to identify which projects need immediate attention.
A5: Rank | B5: Project ID | C5: Institution | D5: Project Name | E5: Category | F5: P | G5: I | H5: β | I5: ARS | J5: Priority | K5: PM Used | L5: RM Used | M5: Complexity | N5: Outcome | O5: Action Required
A6: 1 | B6: P195 | C6: LA Tech | D6: Workday Student | E6: Risk Management | F6: 4.27 | G6: 5 | H6: 0.53 | I6: 9.394 | J6: High | K6: Yes | L6: Yes | M6: High | N6: Delayed | O6: Active mitigation planning required; include in formal risk register
A7: 2 | B7: P053 | C7: RPI | D7: Network services | E7: Risk Management | F7: 4.64 | G7: 4.25 | H7: 0.53 | I7: 8.677 | J7: High | K7: Yes | L7: Yes | M7: High | N7: Delayed | O7: Active mitigation planning required; include in formal risk register
A8: 3 | B8: P107 | C8: RPI | D8: Inventions and patents | E8: Risk Management | F8: 3.91 | G8: 5 | H8: 0.53 | I8: 8.602 | J8: High | K8: No | L8: No | M8: High | N8: Delayed | O8: Active mitigation planning required; include in formal risk register
A9: 4 | B9: P155 | C9: RPI | D9: Email Spam filter | E9: Risk Management | F9: 4.27 | G9: 4.5 | H9: 0.53 | I9: 8.455 | J9: High | K9: Yes | L9: Yes | M9: High | N9: Delayed | O9: Active mitigation planning required; include in formal risk register
A10: 5 | B10: P049 | C10: RPI | D10: Backups | E10: Risk Management | F10: 3.91 | G10: 4.75 | H10: 0.53 | I10: 8.172 | J10: High | K10: Yes | L10: Yes | M10: High | N10: Delayed | O10: Active mitigation planning required; include in formal risk register
A11: 6 | B11: P010 | C11: RPI | D11: Parking Management System | E11: Risk Management | F11: 4.27 | G11: 4.25 | H11: 0.53 | I11: 7.985 | J11: High | K11: No | L11: No | M11: High | N11: Delayed | O11: Active mitigation planning required; include in formal risk register
A12: 7 | B12: P076 | C12: RPI | D12: Payment processing Software (check print | E12: Risk Management | F12: 3.55 | G12: 5 | H12: 0.53 | I12: 7.81 | J12: High | K12: Yes | L12: Yes | M12: High | N12: Delayed | O12: Active mitigation planning required; include in formal risk register
A13: 8 | B13: P122 | C13: RPI | D13: Package Tracking System | E13: Risk Management | F13: 3.55 | G13: 5 | H13: 0.53 | I13: 7.81 | J13: High | K13: Yes | L13: Yes | M13: High | N13: Delayed | O13: Active mitigation planning required; include in formal risk register
A14: 9 | B14: P136 | C14: RPI | D14: Interlibrary loan and document delivery | E14: Risk Management | F14: 3.55 | G14: 5 | H14: 0.53 | I14: 7.81 | J14: High | K14: No | L14: Yes | M14: High | N14: Delayed | O14: Active mitigation planning required; include in formal risk register
A15: 10 | B15: P142 | C15: RPI | D15: Data Warehouse Business Intelligence and | E15: Risk Management | F15: 3.91 | G15: 4.5 | H15: 0.53 | I15: 7.742 | J15: High | K15: Yes | L15: Yes | M15: High | N15: Delayed | O15: Active mitigation planning required; include in formal risk register
A16: 11 | B16: P110 | C16: RPI | D16: Intellectual Property | E16: Risk Management | F16: 5 | G16: 3.5 | H16: 0.53 | I16: 7.7 | J16: High | K16: Yes | L16: Yes | M16: Medium | N16: Failed | O16: Active mitigation planning required; include in formal risk register
A17: 12 | B17: P041 | C17: RPI | D17: Wireless network management | E17: Risk Management | F17: 3.55 | G17: 4.75 | H17: 0.53 | I17: 7.42 | J17: High | K17: Yes | L17: Yes | M17: High | N17: Delayed | O17: Active mitigation planning required; include in formal risk register
... A35: 30 | B35: P091 | C35: RPI | D35: because Microsoft Live is not effective | E35: Organizational Readiness | F35: 2.82 | G35: 4.75 | H35: 0.53 | I35: 5.894 | J35: Moderate | K35: No | L35: Yes | M35: High | N35: Delayed | O35: Periodic monitoring; develop contingency plan at next milestone

Sheet Formula Reference
A2: ARS Formula Reference & Methodology Documentation
B5: THE FORMULA | C5: ARS = P × I × β
B7: VARIABLE | C7: DEFINITION
B8: P — Probability | C8: Likelihood of risk occurring (1–5). In this study derived from Risk_Score_Normalized (0–100) scaled to 1–5.
B9: I — Impact | C9: Severity of consequences (1–5). Derived from project Complexity and risk weighting components, scaled to 1–5.
B10: β — SEM Weight | C10: Standardized path coefficient from IBM AMOS. β = 0.53 for RM→IS (placeholder; update after AMOS run). Reflects empirically-validated causal importance of construct on Implementation Success.
B11: ARS | C11: Adjusted Risk Score. Higher ARS = higher institutional priority. Grounded in SEM causal theory rather than expert judgment alone.
B13: PRIORITY TIERS | C13: CLASSIFICATION & DATASET COUNTS
B14: ARS > 12.0 | C14: CRITICAL — Immediate mitigation. Count in dataset: 0 (0.0%)
B15: ARS 6.0–12.0 | C15: HIGH — Active mitigation required. Count in dataset: 28 (14.4%)
B16: ARS 3.0–6.0 | C16: MODERATE — Periodic monitoring. Count in dataset: 93 (47.7%)
B17: ARS < 3.0 | C17: LOW — Accept with monitoring. Count in dataset: 74 (37.9%)
B19: RM INDICATOR DERIVATION | C19: HOW RM1, RM2, RM3 ARE DERIVED FROM ARS
B20: RM1 — Identification | C20: =6 − ARS_P. High residual probability = poor identification. ARS_P derived from Risk_Score_Normalized scaled to 1–5.
B21: RM2 — Assessment | C21: =6 − ARS_I. High unmitigated impact = poor assessment. ARS_I from Complexity × 1.5 + Severity × 0.3 scaled to 1–5.
B22: RM3 — Mitigation | C22: =(ARS_max − ARS) / (ARS_max − ARS_min) × 4 + 1. High residual ARS = poor mitigation. Full formula used — theoretically grounded in study novel contribution.
B24: KEY CITATIONS | C24: ARS formula: Chapter 3 Section 3.5.4. β weights: Chapter 4 Table 4.9. RM derivation: Dataset v2 Conversion Documentation. PMI PMBOK 7th Ed. ISO 31000. Selvakumar et al. (2024). de Bakker et al. (2010). Goswami (2024).
